Traceback (most recent call last):
  File "/home/ecam/.local/lib/python3.10/site-packages/jupyter_cache/executors/utils.py", line 58, in single_nb_execution
    executenb(
  File "/usr/lib/python3/dist-packages/nbclient/client.py", line 1093, in execute
    return NotebookClient(nb=nb, resources=resources, km=km, **kwargs).execute()
  File "/usr/lib/python3/dist-packages/nbclient/util.py", line 84, in wrapped
    return just_run(coro(*args, **kwargs))
  File "/usr/lib/python3/dist-packages/nbclient/util.py", line 62, in just_run
    return loop.run_until_complete(coro)
  File "/usr/lib/python3.10/asyncio/base_events.py", line 649, in run_until_complete
    return future.result()
  File "/usr/lib/python3/dist-packages/nbclient/client.py", line 559, in async_execute
    await self.async_execute_cell(
  File "/usr/lib/python3/dist-packages/nbclient/client.py", line 854, in async_execute_cell
    self._check_raise_for_error(cell, exec_reply)
  File "/usr/lib/python3/dist-packages/nbclient/client.py", line 756, in _check_raise_for_error
    raise CellExecutionError.from_cell_and_msg(cell, exec_reply_content)
nbclient.exceptions.CellExecutionError: An error occurred while executing the following cell:
------------------
from plotnine.labels import labs
p2 = p2 + labs(
    title = "Main Title",
    subtitle = "a subtitle",
    caption = "A caption",
    tag = "A tag",
    x = "x-axis",
    y = "y-axis"
  )
print(p2)
------------------

[0;31m---------------------------------------------------------------------------[0m
[0;31mPlotnineError[0m                             Traceback (most recent call last)
[0;32m/tmp/ipykernel_1827235/2349479096.py[0m in [0;36m<module>[0;34m[0m
[1;32m      1[0m [0;32mfrom[0m [0mplotnine[0m[0;34m.[0m[0mlabels[0m [0;32mimport[0m [0mlabs[0m[0;34m[0m[0;34m[0m[0m
[0;32m----> 2[0;31m p2 = p2 + labs(
[0m[1;32m      3[0m     [0mtitle[0m [0;34m=[0m [0;34m"Main Title"[0m[0;34m,[0m[0;34m[0m[0;34m[0m[0m
[1;32m      4[0m     [0msubtitle[0m [0;34m=[0m [0;34m"a subtitle"[0m[0;34m,[0m[0;34m[0m[0;34m[0m[0m
[1;32m      5[0m     [0mcaption[0m [0;34m=[0m [0;34m"A caption"[0m[0;34m,[0m[0;34m[0m[0;34m[0m[0m

[0;32m/usr/local/lib/python3.10/dist-packages/plotnine/labels.py[0m in [0;36m__init__[0;34m(self, **kwargs)[0m
[1;32m     30[0m         [0munknown[0m [0;34m=[0m [0mkwargs[0m[0;34m.[0m[0mkeys[0m[0;34m([0m[0;34m)[0m [0;34m-[0m [0mVALID_LABELS[0m[0;34m[0m[0;34m[0m[0m
[1;32m     31[0m         [0;32mif[0m [0munknown[0m[0;34m:[0m[0;34m[0m[0;34m[0m[0m
[0;32m---> 32[0;31m             [0;32mraise[0m [0mPlotnineError[0m[0;34m([0m[0;34mf"Cannot deal with these labels: {unknown}"[0m[0;34m)[0m[0;34m[0m[0;34m[0m[0m
[0m[1;32m     33[0m         [0mself[0m[0;34m.[0m[0mlabels[0m [0;34m=[0m [0mlabels_view[0m[0;34m([0m[0;34m**[0m[0mrename_aesthetics[0m[0;34m([0m[0mkwargs[0m[0;34m)[0m[0;34m)[0m[0;34m[0m[0;34m[0m[0m
[1;32m     34[0m [0;34m[0m[0m

[0;31mPlotnineError[0m: "Cannot deal with these labels: {'tag'}"
PlotnineError: "Cannot deal with these labels: {'tag'}"

